<?xml version="1.0" ?>
<robot name="robot_8">
  <link name="link_0">
    <inertial>
      <origin xyz="4.932958960883266e-17 1.9321397617308664e-20 0.07814699210812621" rpy="0 0 0"/>
      <mass value="0.7140943797276363"/>
      <inertia ixx="0.0020228628385566736" ixy="1.9982351438166168e-19" ixz="-2.46835943485053e-18" iyy="0.002022862838556675" iyz="-2.0367245840675708e-21" izz="0.0008536469142881968"/>
    </inertial>
    <visual>
      <origin xyz="0 0 0" rpy="0 0 0"/>
      <geometry>
        <mesh filename="dae/link_0.dae"/>
      </geometry>
    </visual>
    <collision>
      <origin xyz="0 0 0" rpy="0 0 0"/>
      <geometry>
        <mesh filename="dae/link_0.dae"/>
      </geometry>
    </collision>
  </link>
  <joint name="joint_0" type="revolute">
    <parent link="link_0"/>
    <child link="link_1"/>
    <origin xyz="0.0 0.0 0.1773777473664468" rpy="0 0 0"/>
    <axis xyz="0.0 1.2246467991473532e-16 -1.0"/>
    <limit lower="-1.57" upper="1.57" effort="10" velocity="1"/>
    <dynamics damping="0.1" friction="0.2"/>
  </joint>
  <transmission name="transmission_0">
    <type value="transmission_interface/SimpleTransmission"/>
    <joint name="joint_0"/>
    <hardwareInterface value="hardware_interface/JointPositionInterface"/>
    <actuator name="actuator_0">
      <mechanicalReduction value="1.0"/>
    </actuator>
  </transmission>
  <link name="link_1">
    <inertial>
      <origin xyz="1.3083504584907044e-16 -1.3301889765870135e-16 0.05060493298658221" rpy="0 0 0"/>
      <mass value="0.44566264239607184"/>
      <inertia ixx="0.0010654874970179081" ixy="-1.2263253732333518e-19" ixz="4.138353145433005e-18" iyy="0.0010235582435273807" iyz="3.006216500533614e-18" izz="0.00043342670289637575"/>
    </inertial>
    <visual>
      <origin xyz="0 0 0" rpy="0 0 0"/>
      <geometry>
        <mesh filename="dae/link_1.dae"/>
      </geometry>
    </visual>
    <collision>
      <origin xyz="0 0 0" rpy="0 0 0"/>
      <geometry>
        <mesh filename="dae/link_1.dae"/>
      </geometry>
    </collision>
  </link>
  <joint name="joint_1" type="revolute">
    <parent link="link_1"/>
    <child link="link_2"/>
    <origin xyz="0.0 1.676403534009198e-18 0.11393333671468912" rpy="0 0 0"/>
    <axis xyz="1.0 0.0 0.0"/>
    <limit lower="-1.57" upper="1.57" effort="10" velocity="1"/>
    <dynamics damping="0.1" friction="0.2"/>
  </joint>
  <transmission name="transmission_1">
    <type value="transmission_interface/SimpleTransmission"/>
    <joint name="joint_1"/>
    <hardwareInterface value="hardware_interface/JointPositionInterface"/>
    <actuator name="actuator_1">
      <mechanicalReduction value="1.0"/>
    </actuator>
  </transmission>
  <link name="link_2">
    <inertial>
      <origin xyz="8.447754767839883e-16 1.9494679566377294e-17 0.17818921502174034" rpy="0 0 0"/>
      <mass value="1.1660885052673904"/>
      <inertia ixx="0.014282423043757205" ixy="-3.683838394388993e-21" ixz="-1.6956198387517043e-16" iyy="0.014303963390919269" iyz="1.456379304425365e-17" izz="0.0010758310064459605"/>
    </inertial>
    <visual>
      <origin xyz="0 0 0" rpy="0 0 0"/>
      <geometry>
        <mesh filename="dae/link_2.dae"/>
      </geometry>
    </visual>
    <collision>
      <origin xyz="0 0 0" rpy="0 0 0"/>
      <geometry>
        <mesh filename="dae/link_2.dae"/>
      </geometry>
    </collision>
  </link>
  <joint name="joint_2" type="revolute">
    <parent link="link_2"/>
    <child link="link_3"/>
    <origin xyz="0.0 5.098616525425841e-33 0.37345804583633463" rpy="0 0 0"/>
    <axis xyz="1.0 0.0 0.0"/>
    <limit lower="-1.57" upper="1.57" effort="10" velocity="1"/>
    <dynamics damping="0.1" friction="0.2"/>
  </joint>
  <transmission name="transmission_2">
    <type value="transmission_interface/SimpleTransmission"/>
    <joint name="joint_2"/>
    <hardwareInterface value="hardware_interface/JointPositionInterface"/>
    <actuator name="actuator_2">
      <mechanicalReduction value="1.0"/>
    </actuator>
  </transmission>
  <link name="link_3">
    <inertial>
      <origin xyz="6.177721154282096e-16 4.893195086623024e-17 0.1421827219117961" rpy="0 0 0"/>
      <mass value="0.7410287480524296"/>
      <inertia ixx="0.005697070967712838" ixy="2.305529944045204e-19" ixz="6.484222554343524e-17" iyy="0.005721488878763891" iyz="4.5678891696889074e-18" izz="0.0005517785973250111"/>
    </inertial>
    <visual>
      <origin xyz="0 0 0" rpy="0 0 0"/>
      <geometry>
        <mesh filename="dae/link_3.dae"/>
      </geometry>
    </visual>
    <collision>
      <origin xyz="0 0 0" rpy="0 0 0"/>
      <geometry>
        <mesh filename="dae/link_3.dae"/>
      </geometry>
    </collision>
  </link>
  <joint name="joint_3" type="revolute">
    <parent link="link_3"/>
    <child link="link_4"/>
    <origin xyz="0.0 -5.098616525425841e-33 0.30513189324451606" rpy="0 0 0"/>
    <axis xyz="0.0 1.2246467991473532e-16 -1.0"/>
    <limit lower="-1.57" upper="1.57" effort="10" velocity="1"/>
    <dynamics damping="0.1" friction="0.2"/>
  </joint>
  <transmission name="transmission_3">
    <type value="transmission_interface/SimpleTransmission"/>
    <joint name="joint_3"/>
    <hardwareInterface value="hardware_interface/JointPositionInterface"/>
    <actuator name="actuator_3">
      <mechanicalReduction value="1.0"/>
    </actuator>
  </transmission>
  <link name="link_4">
    <inertial>
      <origin xyz="7.99586972757834e-17 -4.9754481869768227e-17 0.05359276321560263" rpy="0 0 0"/>
      <mass value="0.24942446688583972"/>
      <inertia ixx="0.0004921406057331682" ixy="-6.013727398895277e-20" ixz="1.292267426905869e-18" iyy="0.00048635826630355077" iyz="7.19954785723674e-19" izz="0.0001308606745642267"/>
    </inertial>
    <visual>
      <origin xyz="0 0 0" rpy="0 0 0"/>
      <geometry>
        <mesh filename="dae/link_4.dae"/>
      </geometry>
    </visual>
    <collision>
      <origin xyz="0 0 0" rpy="0 0 0"/>
      <geometry>
        <mesh filename="dae/link_4.dae"/>
      </geometry>
    </collision>
  </link>
  <joint name="joint_4" type="revolute">
    <parent link="link_4"/>
    <child link="link_5"/>
    <origin xyz="0.0 1.2618261037756764e-18 0.1261962373116098" rpy="0 0 0"/>
    <axis xyz="1.0 0.0 0.0"/>
    <limit lower="-1.57" upper="1.57" effort="10" velocity="1"/>
    <dynamics damping="0.1" friction="0.2"/>
  </joint>
  <transmission name="transmission_4">
    <type value="transmission_interface/SimpleTransmission"/>
    <joint name="joint_4"/>
    <hardwareInterface value="hardware_interface/JointPositionInterface"/>
    <actuator name="actuator_4">
      <mechanicalReduction value="1.0"/>
    </actuator>
  </transmission>
  <link name="link_5">
    <inertial>
      <origin xyz="1.979871231687955e-17 7.879205384970502e-17 0.05128497821412464" rpy="0 0 0"/>
      <mass value="0.15374026196024704"/>
      <inertia ixx="0.00021305388909502668" ixy="2.4218751637769674e-20" ixz="-2.2251699219511724e-19" iyy="0.00021919508492575322" iyz="5.582787702398736e-19" izz="6.85403203805626e-05"/>
    </inertial>
    <visual>
      <origin xyz="0 0 0" rpy="0 0 0"/>
      <geometry>
        <mesh filename="dae/link_5.dae"/>
      </geometry>
    </visual>
    <collision>
      <origin xyz="0 0 0" rpy="0 0 0"/>
      <geometry>
        <mesh filename="dae/link_5.dae"/>
      </geometry>
    </collision>
  </link>
  <joint name="joint_5" type="revolute">
    <parent link="link_5"/>
    <child link="link_6"/>
    <origin xyz="0.0 3.3990776836172276e-33 0.11681246518707913" rpy="0 0 0"/>
    <axis xyz="0.0 1.2246467991473532e-16 -1.0"/>
    <limit lower="-1.57" upper="1.57" effort="10" velocity="1"/>
    <dynamics damping="0.1" friction="0.2"/>
  </joint>
  <transmission name="transmission_5">
    <type value="transmission_interface/SimpleTransmission"/>
    <joint name="joint_5"/>
    <hardwareInterface value="hardware_interface/JointPositionInterface"/>
    <actuator name="actuator_5">
      <mechanicalReduction value="1.0"/>
    </actuator>
  </transmission>
  <link name="link_6">
    <inertial>
      <origin xyz="5.71183079590876e-17 -9.011606155750809e-19 0.04461497088658215" rpy="0 0 0"/>
      <mass value="0.12662668238039831"/>
      <inertia ixx="0.00014360866247835636" ixy="-8.729083442807844e-21" ixz="3.438109069178386e-19" iyy="0.00014360866247835642" iyz="5.011825548556848e-21" izz="4.2517341996259525e-05"/>
    </inertial>
    <visual>
      <origin xyz="0 0 0" rpy="0 0 0"/>
      <geometry>
        <mesh filename="dae/link_6.dae"/>
      </geometry>
    </visual>
    <collision>
      <origin xyz="0 0 0" rpy="0 0 0"/>
      <geometry>
        <mesh filename="dae/link_6.dae"/>
      </geometry>
    </collision>
  </link>
</robot>
