<?xml version="1.0" ?>
<robot name="robot_9">
  <link name="link_0">
    <inertial>
      <origin xyz="-4.25050882125368e-16 -5.64918792764883e-19 0.08129184452926942" rpy="0 0 0"/>
      <mass value="0.4095163143536742"/>
      <inertia ixx="0.0010595105634392226" ixy="1.2611829665690793e-20" ixz="5.5473995701031355e-18" iyy="0.0010595105634392155" iyz="-1.4351898567908157e-20" izz="0.0002642175762959311"/>
    </inertial>
    <visual>
      <origin xyz="0 0 0" rpy="0 0 0"/>
      <geometry>
        <mesh filename="dae/link_0.dae"/>
      </geometry>
    </visual>
    <collision>
      <origin xyz="0 0 0" rpy="0 0 0"/>
      <geometry>
        <mesh filename="dae/link_0.dae"/>
      </geometry>
    </collision>
  </link>
  <joint name="joint_0" type="revolute">
    <parent link="link_0"/>
    <child link="link_1"/>
    <origin xyz="0.0 0.0 0.17430892567117615" rpy="0 0 0"/>
    <axis xyz="0.0 1.2246467991473532e-16 -1.0"/>
    <limit lower="-1.57" upper="1.57" effort="10" velocity="1"/>
    <dynamics damping="0.1" friction="0.2"/>
  </joint>
  <transmission name="transmission_0">
    <type value="transmission_interface/SimpleTransmission"/>
    <joint name="joint_0"/>
    <hardwareInterface value="hardware_interface/JointPositionInterface"/>
    <actuator name="actuator_0">
      <mechanicalReduction value="1.0"/>
    </actuator>
  </transmission>
  <link name="link_1">
    <inertial>
      <origin xyz="-1.6507426781846752e-10 -2.5797813383678454e-10 0.04478085853751447" rpy="0 0 0"/>
      <mass value="0.2593510114102806"/>
      <inertia ixx="0.0004946205529737127" ixy="-8.742545481445421e-14" ixz="2.498489885901057e-12" iyy="0.00047779735169463513" iyz="7.335324304180485e-12" izz="0.00016260108586832283"/>
    </inertial>
    <visual>
      <origin xyz="0 0 0" rpy="0 0 0"/>
      <geometry>
        <mesh filename="dae/link_1.dae"/>
      </geometry>
    </visual>
    <collision>
      <origin xyz="0 0 0" rpy="0 0 0"/>
      <geometry>
        <mesh filename="dae/link_1.dae"/>
      </geometry>
    </collision>
  </link>
  <joint name="joint_1" type="revolute">
    <parent link="link_1"/>
    <child link="link_2"/>
    <origin xyz="0.0 1.4884924006958402e-18 0.10923964360426369" rpy="0 0 0"/>
    <axis xyz="1.0 0.0 0.0"/>
    <limit lower="-1.57" upper="1.57" effort="10" velocity="1"/>
    <dynamics damping="0.1" friction="0.2"/>
  </joint>
  <transmission name="transmission_1">
    <type value="transmission_interface/SimpleTransmission"/>
    <joint name="joint_1"/>
    <hardwareInterface value="hardware_interface/JointPositionInterface"/>
    <actuator name="actuator_1">
      <mechanicalReduction value="1.0"/>
    </actuator>
  </transmission>
  <link name="link_2">
    <inertial>
      <origin xyz="1.0625278662989485e-09 -1.0470481933924323e-09 0.17328786272202126" rpy="0 0 0"/>
      <mass value="0.6816043040760718"/>
      <inertia ixx="0.007453256919512177" ixy="-1.0583909322633702e-11" ixz="9.256930962414059e-11" iyy="0.007455426324189141" iyz="-2.0442222602073544e-11" izz="0.0003588144388947336"/>
    </inertial>
    <visual>
      <origin xyz="0 0 0" rpy="0 0 0"/>
      <geometry>
        <mesh filename="dae/link_2.dae"/>
      </geometry>
    </visual>
    <collision>
      <origin xyz="0 0 0" rpy="0 0 0"/>
      <geometry>
        <mesh filename="dae/link_2.dae"/>
      </geometry>
    </collision>
  </link>
  <joint name="joint_2" type="revolute">
    <parent link="link_2"/>
    <child link="link_3"/>
    <origin xyz="0.0 -2.5493082627129206e-33 0.3644636094820475" rpy="0 0 0"/>
    <axis xyz="1.0 0.0 0.0"/>
    <limit lower="-1.57" upper="1.57" effort="10" velocity="1"/>
    <dynamics damping="0.1" friction="0.2"/>
  </joint>
  <transmission name="transmission_2">
    <type value="transmission_interface/SimpleTransmission"/>
    <joint name="joint_2"/>
    <hardwareInterface value="hardware_interface/JointPositionInterface"/>
    <actuator name="actuator_2">
      <mechanicalReduction value="1.0"/>
    </actuator>
  </transmission>
  <link name="link_3">
    <inertial>
      <origin xyz="2.2530975987888012e-10 -1.7006312569457124e-11 0.1430693172763587" rpy="0 0 0"/>
      <mass value="0.44939702244964896"/>
      <inertia ixx="0.0032147660486780004" ixy="-8.277779731069786e-13" ixz="1.2514455436018734e-11" iyy="0.003220760752641335" iyz="-1.3331576248014817e-12" izz="0.00019099505316749808"/>
    </inertial>
    <visual>
      <origin xyz="0 0 0" rpy="0 0 0"/>
      <geometry>
        <mesh filename="dae/link_3.dae"/>
      </geometry>
    </visual>
    <collision>
      <origin xyz="0 0 0" rpy="0 0 0"/>
      <geometry>
        <mesh filename="dae/link_3.dae"/>
      </geometry>
    </collision>
  </link>
  <joint name="joint_3" type="revolute">
    <parent link="link_3"/>
    <child link="link_4"/>
    <origin xyz="0.0 -2.974192973165074e-33 0.29873420036815823" rpy="0 0 0"/>
    <axis xyz="0.0 1.2246467991473532e-16 -1.0"/>
    <limit lower="-1.57" upper="1.57" effort="10" velocity="1"/>
    <dynamics damping="0.1" friction="0.2"/>
  </joint>
  <transmission name="transmission_3">
    <type value="transmission_interface/SimpleTransmission"/>
    <joint name="joint_3"/>
    <hardwareInterface value="hardware_interface/JointPositionInterface"/>
    <actuator name="actuator_3">
      <mechanicalReduction value="1.0"/>
    </actuator>
  </transmission>
  <link name="link_4">
    <inertial>
      <origin xyz="-6.86569276830109e-11 -1.5219497863753006e-10 0.0507313639942323" rpy="0 0 0"/>
      <mass value="0.1561408124720535"/>
      <inertia ixx="0.00027095887051937633" ixy="2.056923818682928e-14" ixz="5.973049430888376e-13" iyy="0.000268259677700759" iyz="2.2847227820126708e-12" izz="5.322161789066068e-05"/>
    </inertial>
    <visual>
      <origin xyz="0 0 0" rpy="0 0 0"/>
      <geometry>
        <mesh filename="dae/link_4.dae"/>
      </geometry>
    </visual>
    <collision>
      <origin xyz="0 0 0" rpy="0 0 0"/>
      <geometry>
        <mesh filename="dae/link_4.dae"/>
      </geometry>
    </collision>
  </link>
  <joint name="joint_4" type="revolute">
    <parent link="link_4"/>
    <child link="link_5"/>
    <origin xyz="0.0 1.133424971005204e-18 0.12374620926298022" rpy="0 0 0"/>
    <axis xyz="1.0 0.0 0.0"/>
    <limit lower="-1.57" upper="1.57" effort="10" velocity="1"/>
    <dynamics damping="0.1" friction="0.2"/>
  </joint>
  <transmission name="transmission_4">
    <type value="transmission_interface/SimpleTransmission"/>
    <joint name="joint_4"/>
    <hardwareInterface value="hardware_interface/JointPositionInterface"/>
    <actuator name="actuator_4">
      <mechanicalReduction value="1.0"/>
    </actuator>
  </transmission>
  <link name="link_5">
    <inertial>
      <origin xyz="1.014465392899467e-09 -4.78934912103783e-10 0.05306367265922886" rpy="0 0 0"/>
      <mass value="0.10075824419925856"/>
      <inertia ixx="0.00011760965982605312" ixy="-9.84135228639241e-13" ixz="4.466913096582549e-12" iyy="0.00011940431824760956" iyz="-2.1289789470806347e-12" izz="2.6979645806046905e-05"/>
    </inertial>
    <visual>
      <origin xyz="0 0 0" rpy="0 0 0"/>
      <geometry>
        <mesh filename="dae/link_5.dae"/>
      </geometry>
    </visual>
    <collision>
      <origin xyz="0 0 0" rpy="0 0 0"/>
      <geometry>
        <mesh filename="dae/link_5.dae"/>
      </geometry>
    </collision>
  </link>
  <joint name="joint_5" type="revolute">
    <parent link="link_5"/>
    <child link="link_6"/>
    <origin xyz="0.0 -2.1244235522607674e-33 0.11355686610373619" rpy="0 0 0"/>
    <axis xyz="0.0 1.2246467991473532e-16 -1.0"/>
    <limit lower="-1.57" upper="1.57" effort="10" velocity="1"/>
    <dynamics damping="0.1" friction="0.2"/>
  </joint>
  <transmission name="transmission_5">
    <type value="transmission_interface/SimpleTransmission"/>
    <joint name="joint_5"/>
    <hardwareInterface value="hardware_interface/JointPositionInterface"/>
    <actuator name="actuator_5">
      <mechanicalReduction value="1.0"/>
    </actuator>
  </transmission>
  <link name="link_6">
    <inertial>
      <origin xyz="1.1940739435161678e-16 1.0389479384937006e-18 0.04438782374804614" rpy="0 0 0"/>
      <mass value="0.09242235726156306"/>
      <inertia ixx="0.00010223314009778667" ixy="-1.1299151993815358e-21" ixz="-2.923218322822487e-19" iyy="0.00010223314009778648" iyz="-1.4766366682269703e-22" izz="2.200452137402907e-05"/>
    </inertial>
    <visual>
      <origin xyz="0 0 0" rpy="0 0 0"/>
      <geometry>
        <mesh filename="dae/link_6.dae"/>
      </geometry>
    </visual>
    <collision>
      <origin xyz="0 0 0" rpy="0 0 0"/>
      <geometry>
        <mesh filename="dae/link_6.dae"/>
      </geometry>
    </collision>
  </link>
</robot>
