<?xml version='1.0' encoding='utf-8'?>
<robot name="robot_9">
  <link name="world" />
  <joint name="world_to_base" type="fixed">
    <parent link="world" />
    <child link="link_0" />
  </joint>
  <gazebo>
    <plugin filename="libign_ros2_control-system.so" name="ign_ros2_control::IgnitionROS2ControlPlugin">
      <parameters>/root/ws/src/torque_controlled_arm/config/controllers.yaml</parameters>
      <controller_manager_node_name>robot_9_2/controller_manager</controller_manager_node_name>
      <ros>
        <namespace>$(arg namespace)</namespace>
      </ros>
    </plugin>
  </gazebo>
  <material name="color_0">
    <color rgba="0.889 0.969 0.015 1" />
  </material>
  <link name="link_0">
    <inertial>
      <origin xyz="-4.25050882125368e-16 -5.64918792764883e-19 0.08129184452926942" rpy="0 0 0" />
      <mass value="0.4095163143536742" />
      <inertia ixx="0.0010595105634392226" ixy="1.2611829665690793e-20" ixz="5.5473995701031355e-18" iyy="0.0010595105634392155" iyz="-1.4351898567908157e-20" izz="0.0002642175762959311" />
    </inertial>
    <visual>
      <origin xyz="0 0 0" rpy="0 0 0" />
      <geometry>
        <mesh filename="/root/ws/src/torque_controlled_arm/robots_p6/robot_9/stl/link_0.stl" />
      </geometry>
      <material name="color_0" />
    </visual>
    <collision>
      <origin xyz="0 0 0" rpy="0 0 0" />
      <geometry>
        <mesh filename="/root/ws/src/torque_controlled_arm/robots_p6/robot_9/stl/link_0.stl" />
      </geometry>
    </collision>
  </link>
  <joint name="joint_0" type="revolute">
    <parent link="link_0" />
    <child link="link_1" />
    <origin xyz="0.0 0.0 0.17430892567117615" rpy="0 0 0" />
    <axis xyz="0.0 1.2246467991473532e-16 -1.0" />
    <limit lower="-6.283185307179586" upper="6.283185307179586" effort="8000.0" velocity="30.0" />
    <dynamics damping="0.05300865746279272" friction="0.3704381544439965" />
  </joint>
  <transmission name="transmission_joint_0">
    <type>transmission_interface/SimpleTransmission</type>
    <joint name="joint_0">
      <hardwareInterface>hardware_interface/EffortJointInterface</hardwareInterface>
    </joint>
    <actuator name="motor_joint_0">
      <hardwareInterface>hardware_interface/EffortJointInterface</hardwareInterface>
      <mechanicalReduction>1</mechanicalReduction>
    </actuator>
  </transmission>
  <gazebo reference="joint_0">
    <implicitSpringDamper>true</implicitSpringDamper>
  </gazebo>
  <material name="color_1">
    <color rgba="0.832 0.971 0.044 1" />
  </material>
  <link name="link_1">
    <inertial>
      <origin xyz="-1.6507426781846752e-10 -2.5797813383678454e-10 0.04478085853751447" rpy="0 0 0" />
      <mass value="0.2593510114102806" />
      <inertia ixx="0.0004946205529737127" ixy="-8.742545481445421e-14" ixz="2.498489885901057e-12" iyy="0.00047779735169463513" iyz="7.335324304180485e-12" izz="0.00016260108586832283" />
    </inertial>
    <visual>
      <origin xyz="0 0 0" rpy="0 0 0" />
      <geometry>
        <mesh filename="/root/ws/src/torque_controlled_arm/robots_p6/robot_9/stl/link_1.stl" />
      </geometry>
      <material name="color_1" />
    </visual>
    <collision>
      <origin xyz="0 0 0" rpy="0 0 0" />
      <geometry>
        <mesh filename="/root/ws/src/torque_controlled_arm/robots_p6/robot_9/stl/link_1.stl" />
      </geometry>
    </collision>
  </link>
  <joint name="joint_1" type="revolute">
    <parent link="link_1" />
    <child link="link_2" />
    <origin xyz="0.0 1.4884924006958402e-18 0.10923964360426369" rpy="0 0 0" />
    <axis xyz="1.0 0.0 0.0" />
    <limit lower="-6.283185307179586" upper="6.283185307179586" effort="8000.0" velocity="30.0" />
    <dynamics damping="0.09534277246563985" friction="0.05813442015990537" />
  </joint>
  <transmission name="transmission_joint_1">
    <type>transmission_interface/SimpleTransmission</type>
    <joint name="joint_1">
      <hardwareInterface>hardware_interface/EffortJointInterface</hardwareInterface>
    </joint>
    <actuator name="motor_joint_1">
      <hardwareInterface>hardware_interface/EffortJointInterface</hardwareInterface>
      <mechanicalReduction>1</mechanicalReduction>
    </actuator>
  </transmission>
  <gazebo reference="joint_1">
    <implicitSpringDamper>true</implicitSpringDamper>
  </gazebo>
  <material name="color_2">
    <color rgba="0.774 0.972 0.072 1" />
  </material>
  <link name="link_2">
    <inertial>
      <origin xyz="1.0625278662989485e-09 -1.0470481933924323e-09 0.17328786272202126" rpy="0 0 0" />
      <mass value="0.6816043040760718" />
      <inertia ixx="0.007453256919512177" ixy="-1.0583909322633702e-11" ixz="9.256930962414059e-11" iyy="0.007455426324189141" iyz="-2.0442222602073544e-11" izz="0.0003588144388947336" />
    </inertial>
    <visual>
      <origin xyz="0 0 0" rpy="0 0 0" />
      <geometry>
        <mesh filename="/root/ws/src/torque_controlled_arm/robots_p6/robot_9/stl/link_2.stl" />
      </geometry>
      <material name="color_2" />
    </visual>
    <collision>
      <origin xyz="0 0 0" rpy="0 0 0" />
      <geometry>
        <mesh filename="/root/ws/src/torque_controlled_arm/robots_p6/robot_9/stl/link_2.stl" />
      </geometry>
    </collision>
  </link>
  <joint name="joint_2" type="revolute">
    <parent link="link_2" />
    <child link="link_3" />
    <origin xyz="0.0 -2.5493082627129206e-33 0.3644636094820475" rpy="0 0 0" />
    <axis xyz="1.0 0.0 0.0" />
    <limit lower="-6.283185307179586" upper="6.283185307179586" effort="8000.0" velocity="30.0" />
    <dynamics damping="0.009343393015569147" friction="0.05677628642878675" />
  </joint>
  <transmission name="transmission_joint_2">
    <type>transmission_interface/SimpleTransmission</type>
    <joint name="joint_2">
      <hardwareInterface>hardware_interface/EffortJointInterface</hardwareInterface>
    </joint>
    <actuator name="motor_joint_2">
      <hardwareInterface>hardware_interface/EffortJointInterface</hardwareInterface>
      <mechanicalReduction>1</mechanicalReduction>
    </actuator>
  </transmission>
  <gazebo reference="joint_2">
    <implicitSpringDamper>true</implicitSpringDamper>
  </gazebo>
  <material name="color_3">
    <color rgba="0.716 0.974 0.100 1" />
  </material>
  <link name="link_3">
    <inertial>
      <origin xyz="2.2530975987888012e-10 -1.7006312569457124e-11 0.1430693172763587" rpy="0 0 0" />
      <mass value="0.44939702244964896" />
      <inertia ixx="0.0032147660486780004" ixy="-8.277779731069786e-13" ixz="1.2514455436018734e-11" iyy="0.003220760752641335" iyz="-1.3331576248014817e-12" izz="0.00019099505316749808" />
    </inertial>
    <visual>
      <origin xyz="0 0 0" rpy="0 0 0" />
      <geometry>
        <mesh filename="/root/ws/src/torque_controlled_arm/robots_p6/robot_9/stl/link_3.stl" />
      </geometry>
      <material name="color_3" />
    </visual>
    <collision>
      <origin xyz="0 0 0" rpy="0 0 0" />
      <geometry>
        <mesh filename="/root/ws/src/torque_controlled_arm/robots_p6/robot_9/stl/link_3.stl" />
      </geometry>
    </collision>
  </link>
  <joint name="joint_3" type="revolute">
    <parent link="link_3" />
    <child link="link_4" />
    <origin xyz="0.0 -2.974192973165074e-33 0.29873420036815823" rpy="0 0 0" />
    <axis xyz="0.0 1.2246467991473532e-16 -1.0" />
    <limit lower="-6.283185307179586" upper="6.283185307179586" effort="8000.0" velocity="30.0" />
    <dynamics damping="0.023315324753420564" friction="0.09529881903562508" />
  </joint>
  <transmission name="transmission_joint_3">
    <type>transmission_interface/SimpleTransmission</type>
    <joint name="joint_3">
      <hardwareInterface>hardware_interface/EffortJointInterface</hardwareInterface>
    </joint>
    <actuator name="motor_joint_3">
      <hardwareInterface>hardware_interface/EffortJointInterface</hardwareInterface>
      <mechanicalReduction>1</mechanicalReduction>
    </actuator>
  </transmission>
  <gazebo reference="joint_3">
    <implicitSpringDamper>true</implicitSpringDamper>
  </gazebo>
  <material name="color_4">
    <color rgba="0.659 0.975 0.128 1" />
  </material>
  <link name="link_4">
    <inertial>
      <origin xyz="-6.86569276830109e-11 -1.5219497863753006e-10 0.0507313639942323" rpy="0 0 0" />
      <mass value="0.1561408124720535" />
      <inertia ixx="0.00027095887051937633" ixy="2.056923818682928e-14" ixz="5.973049430888376e-13" iyy="0.000268259677700759" iyz="2.2847227820126708e-12" izz="5.322161789066068e-05" />
    </inertial>
    <visual>
      <origin xyz="0 0 0" rpy="0 0 0" />
      <geometry>
        <mesh filename="/root/ws/src/torque_controlled_arm/robots_p6/robot_9/stl/link_4.stl" />
      </geometry>
      <material name="color_4" />
    </visual>
    <collision>
      <origin xyz="0 0 0" rpy="0 0 0" />
      <geometry>
        <mesh filename="/root/ws/src/torque_controlled_arm/robots_p6/robot_9/stl/link_4.stl" />
      </geometry>
    </collision>
  </link>
  <joint name="joint_4" type="revolute">
    <parent link="link_4" />
    <child link="link_5" />
    <origin xyz="0.0 1.133424971005204e-18 0.12374620926298022" rpy="0 0 0" />
    <axis xyz="1.0 0.0 0.0" />
    <limit lower="-6.283185307179586" upper="6.283185307179586" effort="8000.0" velocity="30.0" />
    <dynamics damping="0.02476626116964217" friction="0.038451738618234595" />
  </joint>
  <transmission name="transmission_joint_4">
    <type>transmission_interface/SimpleTransmission</type>
    <joint name="joint_4">
      <hardwareInterface>hardware_interface/EffortJointInterface</hardwareInterface>
    </joint>
    <actuator name="motor_joint_4">
      <hardwareInterface>hardware_interface/EffortJointInterface</hardwareInterface>
      <mechanicalReduction>1</mechanicalReduction>
    </actuator>
  </transmission>
  <gazebo reference="joint_4">
    <implicitSpringDamper>true</implicitSpringDamper>
  </gazebo>
  <material name="color_5">
    <color rgba="0.601 0.977 0.156 1" />
  </material>
  <link name="link_5">
    <inertial>
      <origin xyz="1.014465392899467e-09 -4.78934912103783e-10 0.05306367265922886" rpy="0 0 0" />
      <mass value="0.10075824419925856" />
      <inertia ixx="0.00011760965982605312" ixy="-9.84135228639241e-13" ixz="4.466913096582549e-12" iyy="0.00011940431824760956" iyz="-2.1289789470806347e-12" izz="2.6979645806046905e-05" />
    </inertial>
    <visual>
      <origin xyz="0 0 0" rpy="0 0 0" />
      <geometry>
        <mesh filename="/root/ws/src/torque_controlled_arm/robots_p6/robot_9/stl/link_5.stl" />
      </geometry>
      <material name="color_5" />
    </visual>
    <collision>
      <origin xyz="0 0 0" rpy="0 0 0" />
      <geometry>
        <mesh filename="/root/ws/src/torque_controlled_arm/robots_p6/robot_9/stl/link_5.stl" />
      </geometry>
    </collision>
  </link>
  <joint name="joint_5" type="revolute">
    <parent link="link_5" />
    <child link="link_6" />
    <origin xyz="0.0 -2.1244235522607674e-33 0.11355686610373619" rpy="0 0 0" />
    <axis xyz="0.0 1.2246467991473532e-16 -1.0" />
    <limit lower="-6.283185307179586" upper="6.283185307179586" effort="8000.0" velocity="30.0" />
    <dynamics damping="0.022565990152546813" friction="0.03326981936222434" />
  </joint>
  <transmission name="transmission_joint_5">
    <type>transmission_interface/SimpleTransmission</type>
    <joint name="joint_5">
      <hardwareInterface>hardware_interface/EffortJointInterface</hardwareInterface>
    </joint>
    <actuator name="motor_joint_5">
      <hardwareInterface>hardware_interface/EffortJointInterface</hardwareInterface>
      <mechanicalReduction>1</mechanicalReduction>
    </actuator>
  </transmission>
  <gazebo reference="joint_5">
    <implicitSpringDamper>true</implicitSpringDamper>
  </gazebo>
  <material name="color_6">
    <color rgba="0.543 0.978 0.185 1" />
  </material>
  <link name="link_6">
    <inertial>
      <origin xyz="1.1940739435161678e-16 1.0389479384937006e-18 0.04438782374804614" rpy="0 0 0" />
      <mass value="0.09242235726156306" />
      <inertia ixx="0.00010223314009778667" ixy="-1.1299151993815358e-21" ixz="-2.923218322822487e-19" iyy="0.00010223314009778648" iyz="-1.4766366682269703e-22" izz="2.200452137402907e-05" />
    </inertial>
    <visual>
      <origin xyz="0 0 0" rpy="0 0 0" />
      <geometry>
        <mesh filename="/root/ws/src/torque_controlled_arm/robots_p6/robot_9/stl/link_6.stl" />
      </geometry>
      <material name="color_6" />
    </visual>
    <collision>
      <origin xyz="0 0 0" rpy="0 0 0" />
      <geometry>
        <mesh filename="/root/ws/src/torque_controlled_arm/robots_p6/robot_9/stl/link_6.stl" />
      </geometry>
    </collision>
  </link>
  <ros2_control name="robot_0_control" type="system">
    <hardware>
      <plugin>ign_ros2_control/IgnitionSystem</plugin>
    </hardware>
    <joint name="joint_0">
      <command_interface name="effort" />
      <state_interface name="position" />
      <state_interface name="velocity" />
      <state_interface name="effort" />
    </joint>
    <joint name="joint_1">
      <command_interface name="effort" />
      <state_interface name="position" />
      <state_interface name="velocity" />
      <state_interface name="effort" />
    </joint>
    <joint name="joint_2">
      <command_interface name="effort" />
      <state_interface name="position" />
      <state_interface name="velocity" />
      <state_interface name="effort" />
    </joint>
    <joint name="joint_3">
      <command_interface name="effort" />
      <state_interface name="position" />
      <state_interface name="velocity" />
      <state_interface name="effort" />
    </joint>
    <joint name="joint_4">
      <command_interface name="effort" />
      <state_interface name="position" />
      <state_interface name="velocity" />
      <state_interface name="effort" />
    </joint>
    <joint name="joint_5">
      <command_interface name="effort" />
      <state_interface name="position" />
      <state_interface name="velocity" />
      <state_interface name="effort" />
    </joint>
  </ros2_control>
</robot>