<?xml version='1.0' encoding='utf-8'?>
<robot name="robot_4">
  <link name="world" />
  <joint name="world_to_base" type="fixed">
    <parent link="world" />
    <child link="link_0" />
  </joint>
  <gazebo>
    <plugin filename="libign_ros2_control-system.so" name="ign_ros2_control::IgnitionROS2ControlPlugin">
      <parameters>/root/ws/src/torque_controlled_arm/config/controllers.yaml</parameters>
      <controller_manager_node_name>robot_4_0/controller_manager</controller_manager_node_name>
      <ros>
        <namespace>$(arg namespace)</namespace>
      </ros>
    </plugin>
  </gazebo>
  <material name="color_0">
    <color rgba="0.803 0.035 0.830 1" />
  </material>
  <link name="link_0">
    <inertial>
      <origin xyz="-1.5906608694195682e-16 -1.1716028909357261e-18 0.08211269995726088" rpy="0 0 0" />
      <mass value="0.6298188618486545" />
      <inertia ixx="0.0017988380529492555" ixy="3.9739721377114064e-20" ixz="-2.953501893674424e-18" iyy="0.0017988380529492412" iyz="-2.6935530819816658e-20" izz="0.0006116974674870177" />
    </inertial>
    <visual>
      <origin xyz="0 0 0" rpy="0 0 0" />
      <geometry>
        <mesh filename="/root/ws/src/torque_controlled_arm/robots_p6/robot_4/stl/link_0.stl" />
      </geometry>
      <material name="color_0" />
    </visual>
    <collision>
      <origin xyz="0 0 0" rpy="0 0 0" />
      <geometry>
        <mesh filename="/root/ws/src/torque_controlled_arm/robots_p6/robot_4/stl/link_0.stl" />
      </geometry>
    </collision>
  </link>
  <joint name="joint_0" type="revolute">
    <parent link="link_0" />
    <child link="link_1" />
    <origin xyz="0.0 0.0 0.17958714560570016" rpy="0 0 0" />
    <axis xyz="0.0 1.2246467991473532e-16 -1.0" />
    <limit lower="-6.283185307179586" upper="6.283185307179586" effort="8000.0" velocity="30.0" />
    <dynamics damping="0.039478789412966224" friction="0.2582141728375299" />
  </joint>
  <transmission name="transmission_joint_0">
    <type>transmission_interface/SimpleTransmission</type>
    <joint name="joint_0">
      <hardwareInterface>hardware_interface/EffortJointInterface</hardwareInterface>
    </joint>
    <actuator name="motor_joint_0">
      <hardwareInterface>hardware_interface/EffortJointInterface</hardwareInterface>
      <mechanicalReduction>1</mechanicalReduction>
    </actuator>
  </transmission>
  <gazebo reference="joint_0">
    <implicitSpringDamper>true</implicitSpringDamper>
  </gazebo>
  <material name="color_1">
    <color rgba="0.687 0.188 0.844 1" />
  </material>
  <link name="link_1">
    <inertial>
      <origin xyz="4.280898119284248e-11 4.947153572289977e-10 0.048114540475511496" rpy="0 0 0" />
      <mass value="0.42125095889880776" />
      <inertia ixx="0.0010734648812537463" ixy="-1.6394637756739643e-12" ixz="-4.271506010883321e-13" iyy="0.0010239998145801328" iyz="-1.499088453288214e-11" izz="0.00039641745362816794" />
    </inertial>
    <visual>
      <origin xyz="0 0 0" rpy="0 0 0" />
      <geometry>
        <mesh filename="/root/ws/src/torque_controlled_arm/robots_p6/robot_4/stl/link_1.stl" />
      </geometry>
      <material name="color_1" />
    </visual>
    <collision>
      <origin xyz="0 0 0" rpy="0 0 0" />
      <geometry>
        <mesh filename="/root/ws/src/torque_controlled_arm/robots_p6/robot_4/stl/link_1.stl" />
      </geometry>
    </collision>
  </link>
  <joint name="joint_1" type="revolute">
    <parent link="link_1" />
    <child link="link_2" />
    <origin xyz="0.0 1.81169015809637e-18 0.11748222266044611" rpy="0 0 0" />
    <axis xyz="1.0 0.0 0.0" />
    <limit lower="-6.283185307179586" upper="6.283185307179586" effort="8000.0" velocity="30.0" />
    <dynamics damping="0.09648824043423344" friction="0.11939627674373776" />
  </joint>
  <transmission name="transmission_joint_1">
    <type>transmission_interface/SimpleTransmission</type>
    <joint name="joint_1">
      <hardwareInterface>hardware_interface/EffortJointInterface</hardwareInterface>
    </joint>
    <actuator name="motor_joint_1">
      <hardwareInterface>hardware_interface/EffortJointInterface</hardwareInterface>
      <mechanicalReduction>1</mechanicalReduction>
    </actuator>
  </transmission>
  <gazebo reference="joint_1">
    <implicitSpringDamper>true</implicitSpringDamper>
  </gazebo>
  <material name="color_2">
    <color rgba="0.572 0.342 0.858 1" />
  </material>
  <link name="link_2">
    <inertial>
      <origin xyz="6.152510787460749e-10 -1.0113586492829828e-09 0.1800422960493946" rpy="0 0 0" />
      <mass value="1.0802507797663758" />
      <inertia ixx="0.013072085316286949" ixy="-2.0032613657412106e-11" ixz="7.416561480032032e-11" iyy="0.013078924907909156" iyz="1.0805454660932157e-11" izz="0.0008745261440520231" />
    </inertial>
    <visual>
      <origin xyz="0 0 0" rpy="0 0 0" />
      <geometry>
        <mesh filename="/root/ws/src/torque_controlled_arm/robots_p6/robot_4/stl/link_2.stl" />
      </geometry>
      <material name="color_2" />
    </visual>
    <collision>
      <origin xyz="0 0 0" rpy="0 0 0" />
      <geometry>
        <mesh filename="/root/ws/src/torque_controlled_arm/robots_p6/robot_4/stl/link_2.stl" />
      </geometry>
    </collision>
  </link>
  <joint name="joint_2" type="revolute">
    <parent link="link_2" />
    <child link="link_3" />
    <origin xyz="0.0 -3.3990776836172276e-33 0.3798507483563441" rpy="0 0 0" />
    <axis xyz="1.0 0.0 0.0" />
    <limit lower="-6.283185307179586" upper="6.283185307179586" effort="8000.0" velocity="30.0" />
    <dynamics damping="0.07824759325619488" friction="0.1457226956763411" />
  </joint>
  <transmission name="transmission_joint_2">
    <type>transmission_interface/SimpleTransmission</type>
    <joint name="joint_2">
      <hardwareInterface>hardware_interface/EffortJointInterface</hardwareInterface>
    </joint>
    <actuator name="motor_joint_2">
      <hardwareInterface>hardware_interface/EffortJointInterface</hardwareInterface>
      <mechanicalReduction>1</mechanicalReduction>
    </actuator>
  </transmission>
  <gazebo reference="joint_2">
    <implicitSpringDamper>true</implicitSpringDamper>
  </gazebo>
  <material name="color_3">
    <color rgba="0.457 0.495 0.873 1" />
  </material>
  <link name="link_3">
    <inertial>
      <origin xyz="2.6317686213248443e-10 3.756896746629737e-11 0.15074726511302455" rpy="0 0 0" />
      <mass value="0.7366623005685209" />
      <inertia ixx="0.005781793416424981" ixy="-1.8583804973699795e-12" ixz="2.4976270174249282e-11" iyy="0.005799113114226787" iyz="2.705613578529439e-12" izz="0.0004959755744155884" />
    </inertial>
    <visual>
      <origin xyz="0 0 0" rpy="0 0 0" />
      <geometry>
        <mesh filename="/root/ws/src/torque_controlled_arm/robots_p6/robot_4/stl/link_3.stl" />
      </geometry>
      <material name="color_3" />
    </visual>
    <collision>
      <origin xyz="0 0 0" rpy="0 0 0" />
      <geometry>
        <mesh filename="/root/ws/src/torque_controlled_arm/robots_p6/robot_4/stl/link_3.stl" />
      </geometry>
    </collision>
  </link>
  <joint name="joint_3" type="revolute">
    <parent link="link_3" />
    <child link="link_4" />
    <origin xyz="0.0 6.798155367234455e-33 0.31131314048040837" rpy="0 0 0" />
    <axis xyz="0.0 1.2246467991473532e-16 -1.0" />
    <limit lower="-6.283185307179586" upper="6.283185307179586" effort="8000.0" velocity="30.0" />
    <dynamics damping="0.05957493912049259" friction="0.0970131784870479" />
  </joint>
  <transmission name="transmission_joint_3">
    <type>transmission_interface/SimpleTransmission</type>
    <joint name="joint_3">
      <hardwareInterface>hardware_interface/EffortJointInterface</hardwareInterface>
    </joint>
    <actuator name="motor_joint_3">
      <hardwareInterface>hardware_interface/EffortJointInterface</hardwareInterface>
      <mechanicalReduction>1</mechanicalReduction>
    </actuator>
  </transmission>
  <gazebo reference="joint_3">
    <implicitSpringDamper>true</implicitSpringDamper>
  </gazebo>
  <material name="color_4">
    <color rgba="0.342 0.648 0.887 1" />
  </material>
  <link name="link_4">
    <inertial>
      <origin xyz="-1.262465188044805e-10 -1.9992546377540908e-10 0.05267769288683102" rpy="0 0 0" />
      <mass value="0.28093507145962343" />
      <inertia ixx="0.000624017057498945" ixy="-3.978969742346521e-14" ixz="2.4897585997699227e-12" iyy="0.0006134931725319934" iyz="6.4183125126213695e-12" izz="0.00016221820712940068" />
    </inertial>
    <visual>
      <origin xyz="0 0 0" rpy="0 0 0" />
      <geometry>
        <mesh filename="/root/ws/src/torque_controlled_arm/robots_p6/robot_4/stl/link_4.stl" />
      </geometry>
      <material name="color_4" />
    </visual>
    <collision>
      <origin xyz="0 0 0" rpy="0 0 0" />
      <geometry>
        <mesh filename="/root/ws/src/torque_controlled_arm/robots_p6/robot_4/stl/link_4.stl" />
      </geometry>
    </collision>
  </link>
  <joint name="joint_4" type="revolute">
    <parent link="link_4" />
    <child link="link_5" />
    <origin xyz="0.0 1.4661847926333494e-18 0.13117329613595533" rpy="0 0 0" />
    <axis xyz="1.0 0.0 0.0" />
    <limit lower="-6.283185307179586" upper="6.283185307179586" effort="8000.0" velocity="30.0" />
    <dynamics damping="0.06504947330480858" friction="0.00441991705850123" />
  </joint>
  <transmission name="transmission_joint_4">
    <type>transmission_interface/SimpleTransmission</type>
    <joint name="joint_4">
      <hardwareInterface>hardware_interface/EffortJointInterface</hardwareInterface>
    </joint>
    <actuator name="motor_joint_4">
      <hardwareInterface>hardware_interface/EffortJointInterface</hardwareInterface>
      <mechanicalReduction>1</mechanicalReduction>
    </actuator>
  </transmission>
  <gazebo reference="joint_4">
    <implicitSpringDamper>true</implicitSpringDamper>
  </gazebo>
  <material name="color_5">
    <color rgba="0.227 0.802 0.901 1" />
  </material>
  <link name="link_5">
    <inertial>
      <origin xyz="6.729794127175563e-10 -2.058095177993674e-11 0.05904403737292492" rpy="0 0 0" />
      <mass value="0.19495497683321045" />
      <inertia ixx="0.0003038433198934591" ixy="-8.537667759870283e-13" ixz="6.17772714392476e-12" iyy="0.00031084051700053066" iyz="-4.294017999564094e-13" izz="9.236691482615876e-05" />
    </inertial>
    <visual>
      <origin xyz="0 0 0" rpy="0 0 0" />
      <geometry>
        <mesh filename="/root/ws/src/torque_controlled_arm/robots_p6/robot_4/stl/link_5.stl" />
      </geometry>
      <material name="color_5" />
    </visual>
    <collision>
      <origin xyz="0 0 0" rpy="0 0 0" />
      <geometry>
        <mesh filename="/root/ws/src/torque_controlled_arm/robots_p6/robot_4/stl/link_5.stl" />
      </geometry>
    </collision>
  </link>
  <joint name="joint_5" type="revolute">
    <parent link="link_5" />
    <child link="link_6" />
    <origin xyz="0.0 4.673731814973688e-33 0.12643028607162354" rpy="0 0 0" />
    <axis xyz="0.0 1.2246467991473532e-16 -1.0" />
    <limit lower="-6.283185307179586" upper="6.283185307179586" effort="8000.0" velocity="30.0" />
    <dynamics damping="0.02525382120553803" friction="0.04729215296377211" />
  </joint>
  <transmission name="transmission_joint_5">
    <type>transmission_interface/SimpleTransmission</type>
    <joint name="joint_5">
      <hardwareInterface>hardware_interface/EffortJointInterface</hardwareInterface>
    </joint>
    <actuator name="motor_joint_5">
      <hardwareInterface>hardware_interface/EffortJointInterface</hardwareInterface>
      <mechanicalReduction>1</mechanicalReduction>
    </actuator>
  </transmission>
  <gazebo reference="joint_5">
    <implicitSpringDamper>true</implicitSpringDamper>
  </gazebo>
  <material name="color_6">
    <color rgba="0.112 0.955 0.915 1" />
  </material>
  <link name="link_6">
    <inertial>
      <origin xyz="-3.2606556093149573e-16 9.757580797942317e-19 0.04189822878073602" rpy="0 0 0" />
      <mass value="0.1714750717399778" />
      <inertia ixx="0.00021909257008138718" ixy="-3.705237729364269e-21" ixz="1.3328085205426972e-18" iyy="0.00021909257008138566" iyz="4.152749061289183e-21" izz="7.533594827362127e-05" />
    </inertial>
    <visual>
      <origin xyz="0 0 0" rpy="0 0 0" />
      <geometry>
        <mesh filename="/root/ws/src/torque_controlled_arm/robots_p6/robot_4/stl/link_6.stl" />
      </geometry>
      <material name="color_6" />
    </visual>
    <collision>
      <origin xyz="0 0 0" rpy="0 0 0" />
      <geometry>
        <mesh filename="/root/ws/src/torque_controlled_arm/robots_p6/robot_4/stl/link_6.stl" />
      </geometry>
    </collision>
  </link>
  <ros2_control name="robot_0_control" type="system">
    <hardware>
      <plugin>ign_ros2_control/IgnitionSystem</plugin>
    </hardware>
    <joint name="joint_0">
      <command_interface name="effort" />
      <state_interface name="position" />
      <state_interface name="velocity" />
      <state_interface name="effort" />
    </joint>
    <joint name="joint_1">
      <command_interface name="effort" />
      <state_interface name="position" />
      <state_interface name="velocity" />
      <state_interface name="effort" />
    </joint>
    <joint name="joint_2">
      <command_interface name="effort" />
      <state_interface name="position" />
      <state_interface name="velocity" />
      <state_interface name="effort" />
    </joint>
    <joint name="joint_3">
      <command_interface name="effort" />
      <state_interface name="position" />
      <state_interface name="velocity" />
      <state_interface name="effort" />
    </joint>
    <joint name="joint_4">
      <command_interface name="effort" />
      <state_interface name="position" />
      <state_interface name="velocity" />
      <state_interface name="effort" />
    </joint>
    <joint name="joint_5">
      <command_interface name="effort" />
      <state_interface name="position" />
      <state_interface name="velocity" />
      <state_interface name="effort" />
    </joint>
  </ros2_control>
</robot>