<?xml version="1.0" ?>
<robot name="robot_6">
  <link name="link_0">
    <inertial>
      <origin xyz="3.69060631702728e-17 -8.995191101787126e-19 0.0768908511566843" rpy="0 0 0"/>
      <mass value="0.5445854129398837"/>
      <inertia ixx="0.0014357709862446281" ixy="1.0416069062596774e-19" ixz="-1.4900309230797652e-18" iyy="0.0014357709862446281" iyz="-6.7653681330701466e-21" izz="0.0005042537007878779"/>
    </inertial>
    <visual>
      <origin xyz="0 0 0" rpy="0 0 0"/>
      <geometry>
        <mesh filename="dae/link_0.dae"/>
      </geometry>
    </visual>
    <collision>
      <origin xyz="0 0 0" rpy="0 0 0"/>
      <geometry>
        <mesh filename="dae/link_0.dae"/>
      </geometry>
    </collision>
  </link>
  <joint name="joint_0" type="revolute">
    <parent link="link_0"/>
    <child link="link_1"/>
    <origin xyz="0.0 0.0 0.17380169281394378" rpy="0 0 0"/>
    <axis xyz="0.0 1.2246467991473532e-16 -1.0"/>
    <limit lower="-1.57" upper="1.57" effort="10" velocity="1"/>
    <dynamics damping="0.1" friction="0.2"/>
  </joint>
  <transmission name="transmission_0">
    <type value="transmission_interface/SimpleTransmission"/>
    <joint name="joint_0"/>
    <hardwareInterface value="hardware_interface/JointPositionInterface"/>
    <actuator name="actuator_0">
      <mechanicalReduction value="1.0"/>
    </actuator>
  </transmission>
  <link name="link_1">
    <inertial>
      <origin xyz="-1.2157574220533688e-15 -1.2179640848400028e-16 0.05096827289234297" rpy="0 0 0"/>
      <mass value="0.3448104551243379"/>
      <inertia ixx="0.0007185552453500951" ixy="-6.819760202118504e-20" ixz="3.282658000924108e-17" iyy="0.000691693835844752" iyz="1.9673471004593055e-18" izz="0.00026669127314351816"/>
    </inertial>
    <visual>
      <origin xyz="0 0 0" rpy="0 0 0"/>
      <geometry>
        <mesh filename="dae/link_1.dae"/>
      </geometry>
    </visual>
    <collision>
      <origin xyz="0 0 0" rpy="0 0 0"/>
      <geometry>
        <mesh filename="dae/link_1.dae"/>
      </geometry>
    </collision>
  </link>
  <joint name="joint_1" type="revolute">
    <parent link="link_1"/>
    <child link="link_2"/>
    <origin xyz="0.0 1.457433345944241e-18 0.11061590295243301" rpy="0 0 0"/>
    <axis xyz="1.0 0.0 0.0"/>
    <limit lower="-1.57" upper="1.57" effort="10" velocity="1"/>
    <dynamics damping="0.1" friction="0.2"/>
  </joint>
  <transmission name="transmission_1">
    <type value="transmission_interface/SimpleTransmission"/>
    <joint name="joint_1"/>
    <hardwareInterface value="hardware_interface/JointPositionInterface"/>
    <actuator name="actuator_1">
      <mechanicalReduction value="1.0"/>
    </actuator>
  </transmission>
  <link name="link_2">
    <inertial>
      <origin xyz="9.171597742148546e-17 9.655398631916436e-18 0.1786204136260428" rpy="0 0 0"/>
      <mass value="1.0001288579066376"/>
      <inertia ixx="0.011832509492422377" ixy="3.060443317639101e-21" ixz="-2.781320042751667e-16" iyy="0.011843103330305499" iyz="1.047397662989079e-17" izz="0.0007923901676613218"/>
    </inertial>
    <visual>
      <origin xyz="0 0 0" rpy="0 0 0"/>
      <geometry>
        <mesh filename="dae/link_2.dae"/>
      </geometry>
    </visual>
    <collision>
      <origin xyz="0 0 0" rpy="0 0 0"/>
      <geometry>
        <mesh filename="dae/link_2.dae"/>
      </geometry>
    </collision>
  </link>
  <joint name="joint_2" type="revolute">
    <parent link="link_2"/>
    <child link="link_3"/>
    <origin xyz="0.0 -5.948385946330148e-33 0.36846750800326933" rpy="0 0 0"/>
    <axis xyz="1.0 0.0 0.0"/>
    <limit lower="-1.57" upper="1.57" effort="10" velocity="1"/>
    <dynamics damping="0.1" friction="0.2"/>
  </joint>
  <transmission name="transmission_2">
    <type value="transmission_interface/SimpleTransmission"/>
    <joint name="joint_2"/>
    <hardwareInterface value="hardware_interface/JointPositionInterface"/>
    <actuator name="actuator_2">
      <mechanicalReduction value="1.0"/>
    </actuator>
  </transmission>
  <link name="link_3">
    <inertial>
      <origin xyz="6.175021398731943e-16 4.589199333144043e-17 0.13956102667555847" rpy="0 0 0"/>
      <mass value="0.6501898391493608"/>
      <inertia ixx="0.004868819520152307" ixy="1.677052501762501e-19" ixz="5.580257430946471e-17" iyy="0.004887867167032556" iyz="3.891464113183407e-18" izz="0.00042972979118543103"/>
    </inertial>
    <visual>
      <origin xyz="0 0 0" rpy="0 0 0"/>
      <geometry>
        <mesh filename="dae/link_3.dae"/>
      </geometry>
    </visual>
    <collision>
      <origin xyz="0 0 0" rpy="0 0 0"/>
      <geometry>
        <mesh filename="dae/link_3.dae"/>
      </geometry>
    </collision>
  </link>
  <joint name="joint_3" type="revolute">
    <parent link="link_3"/>
    <child link="link_4"/>
    <origin xyz="0.0 -5.948385946330148e-33 0.30190489353790456" rpy="0 0 0"/>
    <axis xyz="0.0 1.2246467991473532e-16 -1.0"/>
    <limit lower="-1.57" upper="1.57" effort="10" velocity="1"/>
    <dynamics damping="0.1" friction="0.2"/>
  </joint>
  <transmission name="transmission_3">
    <type value="transmission_interface/SimpleTransmission"/>
    <joint name="joint_3"/>
    <hardwareInterface value="hardware_interface/JointPositionInterface"/>
    <actuator name="actuator_3">
      <mechanicalReduction value="1.0"/>
    </actuator>
  </transmission>
  <link name="link_4">
    <inertial>
      <origin xyz="1.1047728224589994e-15 -6.371322972285727e-17 0.058831510018701516" rpy="0 0 0"/>
      <mass value="0.2478105548895437"/>
      <inertia ixx="0.0005042001746872454" ixy="-3.967237615170424e-20" ixz="-1.758272854533554e-17" iyy="0.0004963074704542715" iyz="8.541297124545881e-19" izz="0.0001239370399721464"/>
    </inertial>
    <visual>
      <origin xyz="0 0 0" rpy="0 0 0"/>
      <geometry>
        <mesh filename="dae/link_4.dae"/>
      </geometry>
    </visual>
    <collision>
      <origin xyz="0 0 0" rpy="0 0 0"/>
      <geometry>
        <mesh filename="dae/link_4.dae"/>
      </geometry>
    </collision>
  </link>
  <joint name="joint_4" type="revolute">
    <parent link="link_4"/>
    <child link="link_5"/>
    <origin xyz="0.0 1.166677437945965e-18 0.12787811244331596" rpy="0 0 0"/>
    <axis xyz="1.0 0.0 0.0"/>
    <limit lower="-1.57" upper="1.57" effort="10" velocity="1"/>
    <dynamics damping="0.1" friction="0.2"/>
  </joint>
  <transmission name="transmission_4">
    <type value="transmission_interface/SimpleTransmission"/>
    <joint name="joint_4"/>
    <hardwareInterface value="hardware_interface/JointPositionInterface"/>
    <actuator name="actuator_4">
      <mechanicalReduction value="1.0"/>
    </actuator>
  </transmission>
  <link name="link_5">
    <inertial>
      <origin xyz="1.0110570112754976e-15 8.771201827557089e-17 0.05211100414535018" rpy="0 0 0"/>
      <mass value="0.17708913746433186"/>
      <inertia ixx="0.0002627656956327449" ixy="3.020581489649039e-20" ixz="1.0465759581604554e-17" iyy="0.0002711482271184012" iyz="7.250875962537655e-19" izz="8.96801429455661e-05"/>
    </inertial>
    <visual>
      <origin xyz="0 0 0" rpy="0 0 0"/>
      <geometry>
        <mesh filename="dae/link_5.dae"/>
      </geometry>
    </visual>
    <collision>
      <origin xyz="0 0 0" rpy="0 0 0"/>
      <geometry>
        <mesh filename="dae/link_5.dae"/>
      </geometry>
    </collision>
  </link>
  <joint name="joint_5" type="revolute">
    <parent link="link_5"/>
    <child link="link_6"/>
    <origin xyz="0.0 -1.6995388418086138e-33 0.11948095386963738" rpy="0 0 0"/>
    <axis xyz="0.0 1.2246467991473532e-16 -1.0"/>
    <limit lower="-1.57" upper="1.57" effort="10" velocity="1"/>
    <dynamics damping="0.1" friction="0.2"/>
  </joint>
  <transmission name="transmission_5">
    <type value="transmission_interface/SimpleTransmission"/>
    <joint name="joint_5"/>
    <hardwareInterface value="hardware_interface/JointPositionInterface"/>
    <actuator name="actuator_5">
      <mechanicalReduction value="1.0"/>
    </actuator>
  </transmission>
  <link name="link_6">
    <inertial>
      <origin xyz="6.968932136768784e-17 -1.9241734924604582e-19 0.043039869870066735" rpy="0 0 0"/>
      <mass value="0.13531994725155302"/>
      <inertia ixx="0.00015596900004678996" ixy="-1.0546913615493228e-20" ixz="4.309758564067796e-19" iyy="0.00015596900004679002" iyz="-1.2443853839352538e-21" izz="4.881685355087937e-05"/>
    </inertial>
    <visual>
      <origin xyz="0 0 0" rpy="0 0 0"/>
      <geometry>
        <mesh filename="dae/link_6.dae"/>
      </geometry>
    </visual>
    <collision>
      <origin xyz="0 0 0" rpy="0 0 0"/>
      <geometry>
        <mesh filename="dae/link_6.dae"/>
      </geometry>
    </collision>
  </link>
</robot>
