<?xml version='1.0' encoding='utf-8'?>
<robot name="robot_12">
  <link name="world" />
  <joint name="world_to_base" type="fixed">
    <parent link="world" />
    <child link="link_0" />
  </joint>
  <gazebo>
    <plugin filename="libign_ros2_control-system.so" name="ign_ros2_control::IgnitionROS2ControlPlugin">
      <parameters>/root/ws/src/torque_controlled_arm/config/controllers.yaml</parameters>
      <controller_manager_node_name>robot_12_2/controller_manager</controller_manager_node_name>
      <ros>
        <namespace>$(arg namespace)</namespace>
      </ros>
    </plugin>
  </gazebo>
  <material name="color_0">
    <color rgba="0.064 0.413 0.775 1" />
  </material>
  <link name="link_0">
    <inertial>
      <origin xyz="2.853755137417644e-17 -1.8272197189030732e-18 0.07664073455670208" rpy="0 0 0" />
      <mass value="0.4123852063062316" />
      <inertia ixx="0.0010244988792690536" ixy="6.704759006893482e-20" ixz="-8.430764938412726e-19" iyy="0.0010244988792690536" iyz="-2.632209114427586e-20" izz="0.0002917154883969295" />
    </inertial>
    <visual>
      <origin xyz="0 0 0" rpy="0 0 0" />
      <geometry>
        <mesh filename="/root/ws/src/torque_controlled_arm/robots_p6/robot_12/stl/link_0.stl" />
      </geometry>
      <material name="color_0" />
    </visual>
    <collision>
      <origin xyz="0 0 0" rpy="0 0 0" />
      <geometry>
        <mesh filename="/root/ws/src/torque_controlled_arm/robots_p6/robot_12/stl/link_0.stl" />
      </geometry>
    </collision>
  </link>
  <joint name="joint_0" type="revolute">
    <parent link="link_0" />
    <child link="link_1" />
    <origin xyz="0.0 0.0 0.17091628982884677" rpy="0 0 0" />
    <axis xyz="0.0 1.2246467991473532e-16 -1.0" />
    <limit lower="-6.283185307179586" upper="6.283185307179586" effort="8000.0" velocity="30.0" />
    <dynamics damping="0.08087922480621355" friction="0.3531309228798613" />
  </joint>
  <transmission name="transmission_joint_0">
    <type>transmission_interface/SimpleTransmission</type>
    <joint name="joint_0">
      <hardwareInterface>hardware_interface/EffortJointInterface</hardwareInterface>
    </joint>
    <actuator name="motor_joint_0">
      <hardwareInterface>hardware_interface/EffortJointInterface</hardwareInterface>
      <mechanicalReduction>1</mechanicalReduction>
    </actuator>
  </transmission>
  <gazebo reference="joint_0">
    <implicitSpringDamper>true</implicitSpringDamper>
  </gazebo>
  <material name="color_1">
    <color rgba="0.210 0.368 0.680 1" />
  </material>
  <link name="link_1">
    <inertial>
      <origin xyz="1.1636774513974297e-15 -7.243513031665923e-17 0.04418975433503666" rpy="0 0 0" />
      <mass value="0.2199020914833439" />
      <inertia ixx="0.00034927860423678486" ixy="-4.567145729354112e-20" ixz="-1.3745239261882815e-17" iyy="0.0003413213677901376" iyz="7.488504436624024e-19" izz="0.00012111101442334209" />
    </inertial>
    <visual>
      <origin xyz="0 0 0" rpy="0 0 0" />
      <geometry>
        <mesh filename="/root/ws/src/torque_controlled_arm/robots_p6/robot_12/stl/link_1.stl" />
      </geometry>
      <material name="color_1" />
    </visual>
    <collision>
      <origin xyz="0 0 0" rpy="0 0 0" />
      <geometry>
        <mesh filename="/root/ws/src/torque_controlled_arm/robots_p6/robot_12/stl/link_1.stl" />
      </geometry>
    </collision>
  </link>
  <joint name="joint_1" type="revolute">
    <parent link="link_1" />
    <child link="link_2" />
    <origin xyz="0.0 1.2807533694467776e-18 0.10292355140192648" rpy="0 0 0" />
    <axis xyz="1.0 0.0 0.0" />
    <limit lower="-6.283185307179586" upper="6.283185307179586" effort="8000.0" velocity="30.0" />
    <dynamics damping="0.03365404754733529" friction="0.05487538759417335" />
  </joint>
  <transmission name="transmission_joint_1">
    <type>transmission_interface/SimpleTransmission</type>
    <joint name="joint_1">
      <hardwareInterface>hardware_interface/EffortJointInterface</hardwareInterface>
    </joint>
    <actuator name="motor_joint_1">
      <hardwareInterface>hardware_interface/EffortJointInterface</hardwareInterface>
      <mechanicalReduction>1</mechanicalReduction>
    </actuator>
  </transmission>
  <gazebo reference="joint_1">
    <implicitSpringDamper>true</implicitSpringDamper>
  </gazebo>
  <material name="color_2">
    <color rgba="0.355 0.323 0.584 1" />
  </material>
  <link name="link_2">
    <inertial>
      <origin xyz="-9.953466022172898e-17 5.837603354093038e-18 0.1716393125659886" rpy="0 0 0" />
      <mass value="0.5942095775687706" />
      <inertia ixx="0.006311088615470872" ixy="2.6169994243850037e-21" ixz="1.4775966409421713e-16" iyy="0.006314220683139114" iyz="3.755888196904253e-18" izz="0.0002888246846280442" />
    </inertial>
    <visual>
      <origin xyz="0 0 0" rpy="0 0 0" />
      <geometry>
        <mesh filename="/root/ws/src/torque_controlled_arm/robots_p6/robot_12/stl/link_2.stl" />
      </geometry>
      <material name="color_2" />
    </visual>
    <collision>
      <origin xyz="0 0 0" rpy="0 0 0" />
      <geometry>
        <mesh filename="/root/ws/src/torque_controlled_arm/robots_p6/robot_12/stl/link_2.stl" />
      </geometry>
    </collision>
  </link>
  <joint name="joint_2" type="revolute">
    <parent link="link_2" />
    <child link="link_3" />
    <origin xyz="0.0 -5.098616525425841e-33 0.3536858264898504" rpy="0 0 0" />
    <axis xyz="1.0 0.0 0.0" />
    <limit lower="-6.283185307179586" upper="6.283185307179586" effort="8000.0" velocity="30.0" />
    <dynamics damping="0.044340791918599846" friction="0.13561564597852244" />
  </joint>
  <transmission name="transmission_joint_2">
    <type>transmission_interface/SimpleTransmission</type>
    <joint name="joint_2">
      <hardwareInterface>hardware_interface/EffortJointInterface</hardwareInterface>
    </joint>
    <actuator name="motor_joint_2">
      <hardwareInterface>hardware_interface/EffortJointInterface</hardwareInterface>
      <mechanicalReduction>1</mechanicalReduction>
    </actuator>
  </transmission>
  <gazebo reference="joint_2">
    <implicitSpringDamper>true</implicitSpringDamper>
  </gazebo>
  <material name="color_3">
    <color rgba="0.500 0.279 0.488 1" />
  </material>
  <link name="link_3">
    <inertial>
      <origin xyz="-4.851814107036031e-16 2.5943672780283047e-17 0.14151563662098643" rpy="0 0 0" />
      <mass value="0.43114196236514324" />
      <inertia ixx="0.002985376830232748" ixy="9.93698482192402e-20" ixz="-3.122198737414027e-17" iyy="0.0029910259324434367" iyz="1.5080255414652234e-18" izz="0.00018894588852114106" />
    </inertial>
    <visual>
      <origin xyz="0 0 0" rpy="0 0 0" />
      <geometry>
        <mesh filename="/root/ws/src/torque_controlled_arm/robots_p6/robot_12/stl/link_3.stl" />
      </geometry>
      <material name="color_3" />
    </visual>
    <collision>
      <origin xyz="0 0 0" rpy="0 0 0" />
      <geometry>
        <mesh filename="/root/ws/src/torque_controlled_arm/robots_p6/robot_12/stl/link_3.stl" />
      </geometry>
    </collision>
  </link>
  <joint name="joint_3" type="revolute">
    <parent link="link_3" />
    <child link="link_4" />
    <origin xyz="0.0 -5.098616525425841e-33 0.29249914794374027" rpy="0 0 0" />
    <axis xyz="0.0 1.2246467991473532e-16 -1.0" />
    <limit lower="-6.283185307179586" upper="6.283185307179586" effort="8000.0" velocity="30.0" />
    <dynamics damping="0.010270911550987749" friction="0.0007435223478187289" />
  </joint>
  <transmission name="transmission_joint_3">
    <type>transmission_interface/SimpleTransmission</type>
    <joint name="joint_3">
      <hardwareInterface>hardware_interface/EffortJointInterface</hardwareInterface>
    </joint>
    <actuator name="motor_joint_3">
      <hardwareInterface>hardware_interface/EffortJointInterface</hardwareInterface>
      <mechanicalReduction>1</mechanicalReduction>
    </actuator>
  </transmission>
  <gazebo reference="joint_3">
    <implicitSpringDamper>true</implicitSpringDamper>
  </gazebo>
  <material name="color_4">
    <color rgba="0.645 0.234 0.392 1" />
  </material>
  <link name="link_4">
    <inertial>
      <origin xyz="1.0081112529966719e-15 -4.6397568364815145e-17 0.056391544437823765" rpy="0 0 0" />
      <mass value="0.17943062932593376" />
      <inertia ixx="0.0003191347407737156" ixy="-2.5099195181820834e-20" ixz="-1.1238186333107959e-17" iyy="0.0003155644823247639" iyz="4.519933278927822e-19" izz="6.795456438933791e-05" />
    </inertial>
    <visual>
      <origin xyz="0 0 0" rpy="0 0 0" />
      <geometry>
        <mesh filename="/root/ws/src/torque_controlled_arm/robots_p6/robot_12/stl/link_4.stl" />
      </geometry>
      <material name="color_4" />
    </visual>
    <collision>
      <origin xyz="0 0 0" rpy="0 0 0" />
      <geometry>
        <mesh filename="/root/ws/src/torque_controlled_arm/robots_p6/robot_12/stl/link_4.stl" />
      </geometry>
    </collision>
  </link>
  <joint name="joint_4" type="revolute">
    <parent link="link_4" />
    <child link="link_5" />
    <origin xyz="0.0 1.0248378885305842e-18 0.12378801100994666" rpy="0 0 0" />
    <axis xyz="1.0 0.0 0.0" />
    <limit lower="-6.283185307179586" upper="6.283185307179586" effort="8000.0" velocity="30.0" />
    <dynamics damping="0.025487060367071712" friction="0.026204491994524796" />
  </joint>
  <transmission name="transmission_joint_4">
    <type>transmission_interface/SimpleTransmission</type>
    <joint name="joint_4">
      <hardwareInterface>hardware_interface/EffortJointInterface</hardwareInterface>
    </joint>
    <actuator name="motor_joint_4">
      <hardwareInterface>hardware_interface/EffortJointInterface</hardwareInterface>
      <mechanicalReduction>1</mechanicalReduction>
    </actuator>
  </transmission>
  <gazebo reference="joint_4">
    <implicitSpringDamper>true</implicitSpringDamper>
  </gazebo>
  <material name="color_5">
    <color rgba="0.790 0.190 0.297 1" />
  </material>
  <link name="link_5">
    <inertial>
      <origin xyz="8.806991702854012e-16 6.234820108051619e-17 0.051759852376197964" rpy="0 0 0" />
      <mass value="0.1310464961210113" />
      <inertia ixx="0.00016671863369205892" ixy="2.0976416537860397e-20" ixz="6.495542263513479e-18" iyy="0.00017051046510707332" iyz="3.8332302741564753e-19" izz="4.965184344674228e-05" />
    </inertial>
    <visual>
      <origin xyz="0 0 0" rpy="0 0 0" />
      <geometry>
        <mesh filename="/root/ws/src/torque_controlled_arm/robots_p6/robot_12/stl/link_5.stl" />
      </geometry>
      <material name="color_5" />
    </visual>
    <collision>
      <origin xyz="0 0 0" rpy="0 0 0" />
      <geometry>
        <mesh filename="/root/ws/src/torque_controlled_arm/robots_p6/robot_12/stl/link_5.stl" />
      </geometry>
    </collision>
  </link>
  <joint name="joint_5" type="revolute">
    <parent link="link_5" />
    <child link="link_6" />
    <origin xyz="0.0 1.6995388418086138e-33 0.11397432038396715" rpy="0 0 0" />
    <axis xyz="0.0 1.2246467991473532e-16 -1.0" />
    <limit lower="-6.283185307179586" upper="6.283185307179586" effort="8000.0" velocity="30.0" />
    <dynamics damping="0.03174521309404034" friction="0.01077793853515853" />
  </joint>
  <transmission name="transmission_joint_5">
    <type>transmission_interface/SimpleTransmission</type>
    <joint name="joint_5">
      <hardwareInterface>hardware_interface/EffortJointInterface</hardwareInterface>
    </joint>
    <actuator name="motor_joint_5">
      <hardwareInterface>hardware_interface/EffortJointInterface</hardwareInterface>
      <mechanicalReduction>1</mechanicalReduction>
    </actuator>
  </transmission>
  <gazebo reference="joint_5">
    <implicitSpringDamper>true</implicitSpringDamper>
  </gazebo>
  <material name="color_6">
    <color rgba="0.936 0.145 0.201 1" />
  </material>
  <link name="link_6">
    <inertial>
      <origin xyz="5.649890998069268e-17 1.1139604307134125e-18 0.044396251052930234" rpy="0 0 0" />
      <mass value="0.11774594165922542" />
      <inertia ixx="0.000131548680463132" ixy="-7.727260416622278e-21" ixz="2.9947627149157543e-19" iyy="0.00013154868046313212" iyz="5.8582613464534756e-21" izz="3.687631981631145e-05" />
    </inertial>
    <visual>
      <origin xyz="0 0 0" rpy="0 0 0" />
      <geometry>
        <mesh filename="/root/ws/src/torque_controlled_arm/robots_p6/robot_12/stl/link_6.stl" />
      </geometry>
      <material name="color_6" />
    </visual>
    <collision>
      <origin xyz="0 0 0" rpy="0 0 0" />
      <geometry>
        <mesh filename="/root/ws/src/torque_controlled_arm/robots_p6/robot_12/stl/link_6.stl" />
      </geometry>
    </collision>
  </link>
  <ros2_control name="robot_0_control" type="system">
    <hardware>
      <plugin>ign_ros2_control/IgnitionSystem</plugin>
    </hardware>
    <joint name="joint_0">
      <command_interface name="effort" />
      <state_interface name="position" />
      <state_interface name="velocity" />
      <state_interface name="effort" />
    </joint>
    <joint name="joint_1">
      <command_interface name="effort" />
      <state_interface name="position" />
      <state_interface name="velocity" />
      <state_interface name="effort" />
    </joint>
    <joint name="joint_2">
      <command_interface name="effort" />
      <state_interface name="position" />
      <state_interface name="velocity" />
      <state_interface name="effort" />
    </joint>
    <joint name="joint_3">
      <command_interface name="effort" />
      <state_interface name="position" />
      <state_interface name="velocity" />
      <state_interface name="effort" />
    </joint>
    <joint name="joint_4">
      <command_interface name="effort" />
      <state_interface name="position" />
      <state_interface name="velocity" />
      <state_interface name="effort" />
    </joint>
    <joint name="joint_5">
      <command_interface name="effort" />
      <state_interface name="position" />
      <state_interface name="velocity" />
      <state_interface name="effort" />
    </joint>
  </ros2_control>
</robot>